#Try and exception
try:
    """
    The code which can give rise to an exception is written here
    """
    a="10"
    b= int(a)
    print("I am executing")
    print("b =",b)
# except block
except:
    print("Exception caught")

# now lets caught exception
try:
    """
    The code which can give rise to an exception is written here
    """
    a="hagi"
    b= int(a)
    print("I am executing")
    print("b =",b)
except:
    print("Exception caught")
